//Ejercicio: Fix de errores hasta mostrar mensaje retornado por mÃ©todo log() en consola en el catch.
const LogError = require('./log-error');
try{
    throw new LogError('otro error log...');
}
catch(e){
    e.log().then(res => console.log(res)).catch(err => console.log(err.message));
}